Workbook

Sheet Indicadores PFGP
A1: id_indicador | B1: indicador_old | C1: projeto_estruturante | D1: indicador | E1: subtema | F1: embasamento_sugestao | G1: apresentacao_pfgp_2030_02_06 | H1: grupo_fonte | I1: descricao | J1: tipo_cadeia_valor | K1: tipo_marco_logico | L1: dificuldade_obtencao | M1: fonte | N1: limitacoes | O1: status | P1: incluido_radar | Q1: responsavel | R1: dim1 | S1: dim2 | T1: dim3 | U1: dim4 | V1: dim5 | W1: dim6 | X1: freq_coleta | Y1: periodicidade | Z1: memoria_calculo | AA1: desagregacoes | AB1: meta | AC1: mes_ref | AD1: defasagem | AE1: Obs
A2: 13 | D2: Percentual de conclusão do mínimo de 50% do PDI após um ano de ingresso | F2: DIGID | G2: Sim, D4, P13 | H2: Externa à DIGID | J2: Gestão de RH – Atividades e Processos | K2: Produto | L2: 4 | M2: ENAP | N2: Depende de levantamento junto à ENAP ou às UGPs da relação de matriculados no PDI | O2: 2 - A agendar com unidade responsável | U2: 1
A3: 14 | D3: Percentual de conclusão de 100% do PDI após dois anos de ingresso | F3: DIGID | G3: Sim, D4, P13 | H3: Externa à DIGID | J3: Gestão de RH – Atividades e Processos | K3: Produto | L3: 4 | M3: ENAP | N3: Depende de levantamento junto à ENAP ou às UGPs da relação de matriculados no PDI | O3: 2 - A agendar com unidade responsável | U3: 1
A4: 26 | B4: Dimensão 5: Remuneração, Benefícios, Reconhecimento e Recompensas Não Pecuniárias | C4: POLÍTICA FEDERAL DE REMUNERAÇÕES: FOLHA DE PAGAMENTOS E CONSIGNAÇÕES | D4: Percepção de justiça remuneratória | E4: Justiça remuneratória | F4: DIGID | G4: Sim, D2, P6 Sim, D5, P15 | H4: Vozes | I4: Sou remunerado(a) de maneira justa por minha responsabilidade no trabalho.; Sou remunerado(a) de maneira justa pela qualidade do trabalho que apresento.; Comparando-me aos demais servidores públicos efetivos que possuem atribuições semelhantes às minhas, recebo uma remuneração justa. | J4: Gestão de RH – Resultados | K4: Impacto | L4: 1 | M4: Pesquisa Vozes 1 e 2 | O4: 6 - No shiny | S4: 1 | V4: 1
A5: 30 | D5: Percentual de atendimento ao DDFT | F5: DIGID | G5: Sim, D1, P1 | H5: Externa à DIGID | J5: Gestão de RH – Atividades e Processos | K5: Produto | L5: 4 | M5: DEPRO | O5: 4 - Dados em processo de obtenção | R5: 1
A6: 31 | D6: equidade de distribuição dos servidores públicos, vis a vis distribuição demográfica na população, por: 1) gênero; 2) raça; 3) origem territorial; 4) faixa etária | E6: Equidade de acesso | F6: DIGID | G6: Sim, D1, P2 | H6: SIGEPE /Censo Demográfico | J6: Gestão de RH – Resultados | K6: Impacto | L6: 1 | M6: SIAPE | N6: Servidores Estatutários? | O6: 6 - No shiny | P6: Sim | R6: 1
A7: 32 | D7: Distribuição planejada por forma de provimento (estatutário, temporário, emprego público, comissionado) | E7: Provimento | F7: DIGID | G7: Sim, D1, P3 | H7: Externa à DIGID | J7: Gestão de RH – Atividades e Processos | K7: Atividade | L7: 5 | M7: DEPRO | N7: Depende de dados de provimento de vagas (DEPRO) | O7: 4 - Dados em processo de obtenção | R7: 1
A8: 33 | D8: Distribuição observada por forma de provimento (estatutário, temporário, emprego público, comissionado) | E8: Provimento | F8: DIGID | G8: Sim, D1, P3 | H8: SIGEPE | J8: Gestão de RH – Atividades e Processos | K8: Produto | L8: 1 | M8: SIAPE | O8: 5 - Dados disponíveis/obtidos | R8: 1
A9: 34 | D9: Percentual de servidores movimentados entre áreas temáticas, órgãos ou secretarias (de carreiras transversais / não transversais) | F9: DIGID | G9: Sim, D1, P4 | H9: SIGEPE | J9: Gestão de RH – Atividades e Processos | K9: Produto | L9: 3 | M9: SIAPE | N9: Depende da elaboração do rastreio de mudanças no nome das UORGs, órgãos e secretarias. Depende da construção longitudinal das UORGs de vínculo por CPF/matrícula SIAPE | O9: 5 - Dados disponíveis/obtidos | R9: 1
A10: 35 | D10: indicadores de turnover; | F10: DIGID | G10: Sim, D3, P7 Sim, D3, P8 Sim, D3, P10 | H10: SIGEPE | J10: Objetivos organizacionais | K10: Resultado | L10: 3 | M10: SIAPE | N10: Depende da elaboração do rastreio de mudanças no nome das UORGs, órgãos e secretarias. Depende da construção longitudinal das UORGs de vínculo por CPF/matrícula SIAPE | O10: 5 - Dados disponíveis/obtidos | T10: 1
A11: 36 | D11: Taxa de absenteísmo; | F11: DIGID | G11: Sim, D3, P9 Sim, D3, P8 | H11: SIASS | J11: Gestão de RH – Resultados | K11: Resultado | L11: 2 | M11: SIAPE | O11: 5 - Dados disponíveis/obtidos | T11: 1
A12: 37 | D12: Taxa de absenteísmo por determinadas CID´s; | F12: DIGID | G12: Sim, D3, P9 | H12: SIASS | J12: Gestão de RH – Resultados | K12: Impacto | L12: 4 | M12: SIASS | N12: Depende de acesso ao SIASS (DIPAS) | O12: 4 - Dados em processo de obtenção | T12: 1
A13: 38 | D13: Percepção de segurança psicológica | E13: Clima organizacional | F13: DIGID | G13: Sim, D3, P7 Sim, D3, P8 Sim, D3, P9 Sim, D3, P10 | H13: Vozes | I13: Na minha equipe, as pessoas diferentes são acolhidas.; É fácil pedir ajuda a outros membros dessa equipe.; Membros da minha equipe respeitam e valorizam as contribuições uns dos outros. | J13: Objetivos organizacionais | K13: Impacto | L13: 1 | M13: Pesquisa Vozes 1 e 2 | O13: 6 - No shiny | T13: 1
A14: 39 | D14: Percentual de servidores submetidos à avaliação de desempenho | F14: DIGID | G14: Sim, D4, P11 | H14: Externa à DIGID | J14: Gestão de RH – Atividades e Processos | K14: Produto | L14: 5 | M14: Mapear fonte | N14: Depende de acesso a dados com a unidade responsável | O14: 1 - Mapear fonte | U14: 1
A15: 40 | D15: % de servidores submetidos à avaliação de desempenho 360º (?) | F15: DIGID | G15: Não | H15: _ | K15: Produto | L15: 5 | N15: Depende de acesso a dados com a unidade responsável | O15: A avaliar | U15: 1
A16: 41 | D16: Percentual de servidores com mapeamento do perfil de competências / perfil profissiográfico | F16: DIGID | G16: Sim, D3, P7 Sim, D4, P13 | H16: Externa à DIGID | J16: Gestão de RH – Atividades e Processos | K16: Produto | L16: 5 | M16: Mapear fonte | N16: Depende de acesso a dados com a unidade responsável | O16: 1 - Mapear fonte | T16: 1 | U16: 1
A17: 42 | D17: Percentual de órgãos com PNDP atualizado | F17: DIGID | G17: Sim, D4, P12 | H17: Externa à DIGID | J17: Gestão de RH – Atividades e Processos | K17: Insumo | L17: 5 | M17: Mapear fonte | N17: Depende de acesso a dados com a unidade responsável | O17: 1 - Mapear fonte | U17: 1
A18: 43 | D18: Percentual de atendimento do PNDP | F18: DIGID | G18: Sim, D4, P12 | H18: Externa à DIGID | J18: Gestão de RH – Atividades e Processos | K18: Produto | L18: 5 | M18: Mapear fonte | N18: Depende de acesso a dados com a unidade responsável | O18: 1 - Mapear fonte | U18: 1
A19: 44 | D19: % de servidores submetidos à avaliação de competências de liderança | F19: DIGID | G19: Não | H19: Insistir no retorno? | K19: Produto | L19: 5 | N19: Depende de acesso a dados com a unidade responsável | O19: A avaliar | T19: 1 | U19: 1
A20: 45 | D20: número de servidores formados pelo LideraGov por: 1) gênero; 2) raça; 3) origem territorial; 4) faixa etária | E20: Liderança | F20: DIGID | G20: Sim, D4, P14 | H20: Externa à DIGID | J20: Gestão de RH – Atividades e Processos | K20: Produto | L20: 5 | M20: ENAP | N20: Depende de acesso a dados com a unidade responsável | O20: 3 - Reunião agendada com unidade responsável | U20: 1
A21: 46 | D21: Percentual de cargos de liderança reservados a servidores estatutários | E21: Liderança | F21: DIGID | G21: Sim, D4, P14 | H21: Externa à DIGID | J21: Gestão de RH – Atividades e Processos | K21: Insumo | L21: 5 | M21: Mapear fonte | N21: Depende de acesso a dados com a unidade responsável | O21: 1 - Mapear fonte | U21: 1
A22: 47 | D22: Percentual de cargos de liderança reservados a mulheres | E22: Liderança | F22: DIGID | G22: Sim, D4, P14 | H22: Externa à DIGID | J22: Gestão de RH – Atividades e Processos | K22: Insumo | L22: 5 | M22: Mapear fonte | N22: Depende de acesso a dados com a unidade responsável | O22: 1 - Mapear fonte | U22: 1
A23: 48 | D23: Percentual de cargos de liderança reservados a pessoas negras | E23: Liderança | F23: DIGID | G23: Sim, D4, P14 | H23: Externa à DIGID | J23: Gestão de RH – Atividades e Processos | K23: Insumo | L23: 5 | M23: Mapear fonte | N23: Depende de acesso a dados com a unidade responsável | O23: 1 - Mapear fonte | U23: 1
A24: 49 | D24: Percentual de cargos de liderança ocupados por pessoas negras | E24: Liderança | F24: DIGID | G24: Sim, D4, P14 | H24: SIGEPE | J24: Gestão de RH – Atividades e Processos | K24: Resultado | L24: 1 | M24: SIAPE | O24: 6 - No shiny | U24: 1
A25: 50 | D25: Percentual de cargos de liderança ocupados por mulheres | E25: Liderança | F25: DIGID | G25: Sim, D4, P14 | H25: SIGEPE | J25: Gestão de RH – Atividades e Processos | K25: Resultado | L25: 1 | M25: SIAPE | O25: 6 - No shiny | P25: Sim | U25: 1
A26: 51 | D26: Percentual de cargos de liderança ocupados por servidores estatutários | E26: Liderança | F26: DIGID | G26: Sim, D4, P14 | H26: SIGEPE | J26: Gestão de RH – Atividades e Processos | K26: Resultado | L26: 1 | M26: SIAPE | O26: 6 - No shiny | U26: 1
A27: 52 | D27: Percentual de cargos de liderança por origem territorial | E27: Liderança | F27: DIGID | G27: Sim, D4, P14 | H27: SIGEPE | J27: Gestão de RH – Atividades e Processos | K27: Impacto | L27: 1 | M27: SIAPE | O27: 6 - No shiny | U27: 1
A28: 53 | D28: indicadores de turnover de lideranças | E28: Liderança | F28: DIGID | G28: Sim, D4, P14 | H28: SIGEPE | J28: Gestão de RH – Atividades e Processos | K28: Impacto | L28: 1 | M28: SIAPE | O28: 5 - Dados disponíveis/obtidos | U28: 1
A29: 54 | D29: Oportunidade de capacitação | E29: Capacitação | F29: DIGID | G29: Sim, D4, P12 | H29: Vozes | I29: Vozes - Tenho oportunidades de capacitação suficientes no trabalho para desempenhar minhas tarefas com qualidade. | J29: Gestão de RH – Atividades e Processos | K29: Impacto | L29: 1 | M29: Pesquisa Vozes 2 | O29: 6 - No shiny | U29: 1
A30: 55 | D30: Percepções da relação Liderança - servidor(a) | E30: Liderança | F30: DIGID | G30: Não | H30: Vozes - insistir no retorno? | I30: Vozes - Liderança - servidor(a) : Conversa comigo sobre o meu desempenho.; Ajuda a definir ações para aperfeiçoar o meu desempenho.; Oferece apoio técnico quando converso sobre dificuldades na execução das tarefas.; | K30: Impacto | L30: 1 | M30: Pesquisa Vozes 2 | O30: Dados Obtidos | U30: 1
A31: 56 | D31: Percepções da relação Liderança - equipe | E31: Liderança | F31: DIGID | G31: Não | H31: Vozes - insistir no retorno? | I31: Liderança - equipe: Orienta a equipe sobre objetivos a serem alcançados em determinado prazo.; Informa à equipe como os objetivos se alinham à estratégia da organização.; Estabelece com a equipe metas realizáveis.; Considera a complexidade das atividades na definição dos prazos das entregas da equipe.; Reforça a importância das entregas da equipe e as consequências de não as realizar.; Emprega esforços para o bem-estar da equipe.; Incentiva a colaboração entre membros da equipe.; Incentiva a equipe a apresentar ideias e sugestões sobre o trabalho.; Respeita as ideias dos membros da equipe.; Comunica à equipe se a entrega está sendo executada conforme os critérios pactuados.; Planeja com a equipe formas de corrigir erros na execução das entregas.; Reconhece as contribuições da equipe para o alcance das metas. | K31: Impacto | L31: 1 | M31: Pesquisa Vozes 2 | O31: Dados Obtidos | T31: 1 | U31: 1
A32: 57 | D32: Percepções das atitudes de liderança | E32: Liderança | F32: DIGID | G32: Não | H32: Vozes - insistir no retorno? | I32: Assegura que a equipe tenha um entendimento claro do seu propósito. Sugere novas formas de se pensar como realizar o trabalho Fomenta um ambiente que valoriza a comunicação transparente e profissional Ajuda diferentes equipes a se comunicarem entre si Promove interesses da unidade em equilíbrio com as necessidades dos usuários finais Age como um mentor, compartilhando experiências e lições aprendidas Busca constantemente oportunidades de autodesenvolvimento com base na identificação de seus pontos fortes e necessidades de desenvolvimento. Incentiva membros da equipe a participarem de ações de desenvolvimento (curso, oficina, palestra, congresso, entre outros). Ajuda a equipe a desenvolver soluções para problemas de relacionamento Comunica o que é esperado da equipe | K32: Impacto | L32: 1 | M32: Pesquisa Vozes 1 | O32: Dados Obtidos | T32: 1 | U32: 1
A33: 58 | D33: Percentual do número de cargos em carreiras transversais | E33: Carreiras | F33: DIGID | G33: Sim, D2, P5 | H33: SIGEPE | J33: Gestão de RH – Atividades e Processos | K33: Resultado | L33: 1 | M33: SIAPE | O33: 6 - No shiny | S33: 1
A34: 59 | D34: Percentual de servidores ativos em carreiras transversais | E34: Carreiras | F34: DIGID | G34: Sim, D2, P5 | H34: SIGEPE | J34: Gestão de RH – Atividades e Processos | K34: Resultado | L34: 1 | M34: SIAPE | O34: 6 - No shiny | S34: 1
A35: 60 | D35: Percentual de servidoras mulheres em carreiras transversais / não transversais / total | E35: Carreiras | F35: DIGID | G35: Sim, D2, P5 | H35: SIGEPE | J35: Gestão de RH – Atividades e Processos | K35: Resultado | L35: 1 | M35: SIAPE | O35: 6 - No shiny | S35: 1
A36: 61 | D36: Percentual de servidores negros em carreiras transversais / não transversais / total | E36: Carreiras | F36: DIGID | G36: Sim, D2, P5 | H36: SIGEPE | J36: Gestão de RH – Atividades e Processos | K36: Resultado | L36: 1 | M36: SIAPE | O36: 6 - No shiny | S36: 1
A37: 62 | D37: Percentual do número de cargos no PGPE e em Plano de Cargos Especiais (sem carreiras) | E37: Carreiras | F37: DIGID | G37: Sim, D2, P5 | H37: SIGEPE | J37: Gestão de RH – Atividades e Processos | K37: Resultado | L37: 1 | M37: SIAPE | O37: 5 - Dados disponíveis/obtidos | S37: 1
A38: 66 | D38: Percepção de justiça remuneratória | E38: Justiça remuneratória | F38: DIGID | G38: repetido | H38: _ | I38: Sou remunerado(a) de maneira justa por minha responsabilidade no trabalho.; Sou remunerado(a) de maneira justa pela qualidade do trabalho que apresento.; Comparando-me aos demais servidores públicos efetivos que possuem atribuições semelhantes às minhas, recebo uma remuneração justa. | J38: Gestão de RH – Resultados | K38: Impacto | L38: 1 | M38: Pesquisa Vozes 1 e 2 | O38: Dados Obtidos | S38: 1 | V38: 1
A39: 67 | D39: Percepções sobre critérios de promoção | E39: Promoção | F39: DIGID | G39: Sim, D2, P6 | H39: Vozes | I39: Vozes - Critérios de promoção: Experiência profissional; Desempenho profissional; Formação educacional; Redes de relacionamento; Apoio de um político ou de alguém com conexões políticas | J39: Gestão de RH – Resultados | K39: Impacto | L39: 1 | M39: Pesquisa Vozes 1 e 2 | O39: 6 - No shiny | S39: 1 | U39: DIGID | V39: 1
A40: 70 | D40: Satisfação no trabalho | E40: Clima organizacional | F40: DIGID | G40: Sim, D5, P16 | H40: Vozes | I40: Vozes - Estou satisfeito(a) com meu trabalho.; Quero deixar de trabalhar no setor público. | J40: Gestão de RH – Resultados | K40: Impacto | L40: 1 | M40: Pesquisa Vozes 1 e 2 | O40: 6 - No shiny | V40: 1
...

Sheet Mapeamento informações
A1: id_indicador | B1: Indicador | C1: Indicador_copy | D1: Conceito | E1: Campo | F1: Descrição | G1: Unidade Responsável | H1: Sistema | I1: Tabela
A2: 0 | B2: Agregações mínimas | C2: Agregações mínimas | D2: Órgão | E2: SG_ORGAO | F2: Sigla do Órgão | G2: DIGID | H2: DataBricks | I2: Tabelão
A3: 0 | B3: Agregações mínimas | C3: Agregações mínimas | D3: Órgão | E3: CO_ORGAO | F3: Código do Órgão | G3: DIGID | H3: DataBricks | I3: Tabelão
A4: 0 | B4: Agregações mínimas | C4: Agregações mínimas | D4: Órgão | E4: COD ÓRGÃO | F4: Código do Órgão | G4: DIGID | H4: DW-SIAPE | I4: Tabelão
A5: 0 | B5: Agregações mínimas | C5: Agregações mínimas | D5: Órgão | E5: ÓRGÃO | F5: Nome do Órgão | G5: DIGID | H5: DW-SIAPE
A6: 0 | B6: Agregações mínimas | C6: Agregações mínimas | D6: Órgão | E6: NO_ORGAO | F6: Nome do Órgão | G6: DIGID | H6: DataBricks | I6: Tabelão
A7: 0 | B7: Agregações mínimas | C7: Agregações mínimas | D7: Natureza Jurídica | E7: NO_NATUREZA_JURIDICA | F7: Agrupamento de Natureza Jurídica (definição DW) | G7: DIGID | H7: DataBricks | I7: Tabelão
A8: 0 | B8: Agregações mínimas | C8: Agregações mínimas | D8: Natureza Jurídica | E8: agrup_orgao2 | F8: Agrupamento de Natureza Jurídica (Definição Vozes) | G8: DIGID | H8: Arquivo CSV | I8: Pesquisa Vozes
A9: 0 | B9: Agregações mínimas | C9: Agregações mínimas | D9: Natureza Jurídica | E9: NATUREZA JURÍDICA | F9: Agrupamento de Natureza Jurídica (definição DW) | G9: DIGID | H9: DW-SIAPE
A10: 0 | B10: Agregações mínimas | C10: Agregações mínimas | D10: Cor/origem étnica | E10: NO_COR_ORIGEM_ETNICA | F10: Cor/origem étnica | G10: DIGID | H10: DataBricks | I10: Tabelão
A11: 0 | B11: Agregações mínimas | C11: Agregações mínimas | D11: Cor/origem étnica | E11: COR ORIGEM ETNICA | F11: Cor/origem étnica | G11: DIGID | H11: DW-SIAPE
A12: 0 | B12: Agregações mínimas | C12: Agregações mínimas | D12: Sexo | E12: CO_SEXO | F12: Código Sexo | G12: DIGID | H12: DataBricks | I12: Tabelão
A13: 0 | B13: Agregações mínimas | C13: Agregações mínimas | D13: Sexo | E13: SEXO | F13: Sexo | G13: DIGID | H13: DW-SIAPE
A14: 0 | B14: Agregações mínimas | C14: Agregações mínimas | D14: Naturalidade | E14: CO_UF_NATURALIDADE | F14: UF de NATURALIDADE | G14: DIGID | H14: DataBricks | I14: Tabelão
A15: 0 | B15: Agregações mínimas | C15: Agregações mínimas | D15: Naturalidade | E15: NO_REGIAO_NATURALIDADE | F15: Regiao de naturalidade | G15: DIGID | H15: DataBricks | I15: Tabelão
A16: 0 | B16: Agregações mínimas | C16: Agregações mínimas | D16: Naturalidade | E16: UF NATURALIDADE | F16: UF de NATURALIDADE | G16: DIGID | H16: DW-SIAPE
A17: 0 | B17: Agregações mínimas | C17: Agregações mínimas | D17: Período (mês ou ano) | E17: MÊS | F17: Mês-ano de referência (Mmm AAAA, ex. Dez 2026) | G17: DIGID | H17: DW-SIAPE
A18: 4 | B18: =VLOOKUP(A18,'Indicadores PFGP'!A$2:$D$89,4,0) -> Percentual de Pessoas Negras em Liderança | C18: Percentual de Pessoas Negras em Liderança | D18: Função | E18: FUNÇÃO | F18: Função | G18: DIGID | H18: DW-SIAPE
A19: 4 | B19: =VLOOKUP(A19,'Indicadores PFGP'!A$2:$D$89,4,0) -> Percentual de Pessoas Negras em Liderança | C19: Percentual de Pessoas Negras em Liderança | D19: Nível da função | E19: NÍVEL FUNÇÃO | F19: Nível da função | G19: DIGID | H19: DW-SIAPE
A20: 4 | B20: =VLOOKUP(A20,'Indicadores PFGP'!A$2:$D$89,4,0) -> Percentual de Pessoas Negras em Liderança | C20: Percentual de Pessoas Negras em Liderança | D20: Função | E20: SG_FUNCAO | F20: Função | G20: DIGID | H20: DataBricks | I20: Tabelão
A21: 4 | B21: =VLOOKUP(A21,'Indicadores PFGP'!A$2:$D$89,4,0) -> Percentual de Pessoas Negras em Liderança | C21: Percentual de Pessoas Negras em Liderança | D21: Nível da função | E21: CO_NIVEL_FUNCAO | F21: Código do Nível da função | G21: DIGID | H21: DataBricks | I21: Tabelão
A22: 4 | B22: =VLOOKUP(A22,'Indicadores PFGP'!A$2:$D$89,4,0) -> Percentual de Pessoas Negras em Liderança | C22: Percentual de Pessoas Negras em Liderança | D22: Nível da função | E22: SG_NIV_FUN | F22: Nível da função | G22: DIGID | H22: DataBricks | I22: Tabelão
A23: 4 | B23: =VLOOKUP(A23,'Indicadores PFGP'!A$2:$D$89,4,0) -> Percentual de Pessoas Negras em Liderança | C23: Percentual de Pessoas Negras em Liderança | D23: Cor/origem étnica | E23: COR ORIGEM ETNICA | F23: Cor/origem étnica | G23: DIGID | H23: DW-SIAPE
A24: 4 | B24: =VLOOKUP(A24,'Indicadores PFGP'!A$2:$D$89,4,0) -> Percentual de Pessoas Negras em Liderança | C24: Percentual de Pessoas Negras em Liderança | D24: Cor/origem étnica | E24: NO_COR_ORIGEM_ETNICA | F24: Cor/origem étnica | G24: DIGID | H24: DataBricks | I24: Tabelão
A25: 50 | B25: =VLOOKUP(A25,'Indicadores PFGP'!A$2:$D$89,4,0) -> Percentual de cargos de liderança ocupados por mulheres | C25: % de cargos de liderança ocupados por mulheres | D25: Função | E25: FUNÇÃO | F25: Função | G25: DIGID | H25: DW-SIAPE
A26: 50 | B26: =VLOOKUP(A26,'Indicadores PFGP'!A$2:$D$89,4,0) -> Percentual de cargos de liderança ocupados por mulheres | C26: % de cargos de liderança ocupados por mulheres | D26: Nível da função | E26: NÍVEL FUNÇÃO | F26: Nível da função | G26: DIGID | H26: DW-SIAPE
A27: 50 | B27: =VLOOKUP(A27,'Indicadores PFGP'!A$2:$D$89,4,0) -> Percentual de cargos de liderança ocupados por mulheres | C27: % de cargos de liderança ocupados por mulheres | D27: Função | E27: SG_FUNCAO | F27: Função | G27: DIGID | H27: DataBricks | I27: Tabelão
A28: 50 | B28: =VLOOKUP(A28,'Indicadores PFGP'!A$2:$D$89,4,0) -> Percentual de cargos de liderança ocupados por mulheres | C28: % de cargos de liderança ocupados por mulheres | D28: Nível da função | E28: CO_NIVEL_FUNCAO | F28: Código do Nível da função | G28: DIGID | H28: DataBricks | I28: Tabelão
A29: 50 | B29: =VLOOKUP(A29,'Indicadores PFGP'!A$2:$D$89,4,0) -> Percentual de cargos de liderança ocupados por mulheres | C29: % de cargos de liderança ocupados por mulheres | D29: Nível da função | E29: SG_NIV_FUN | F29: Nível da função | G29: DIGID | H29: DataBricks | I29: Tabelão
A30: 50 | B30: =VLOOKUP(A30,'Indicadores PFGP'!A$2:$D$89,4,0) -> Percentual de cargos de liderança ocupados por mulheres | C30: % de cargos de liderança ocupados por mulheres | D30: Sexo | E30: SEXO | F30: Sexo | G30: DIGID | H30: DW-SIAPE
A31: 50 | B31: =VLOOKUP(A31,'Indicadores PFGP'!A$2:$D$89,4,0) -> Percentual de cargos de liderança ocupados por mulheres | C31: % de cargos de liderança ocupados por mulheres | D31: Sexo | E31: CO_SEXO | F31: Código Sexo | G31: DIGID | H31: DataBricks | I31: Tabelão
A32: 51 | B32: =VLOOKUP(A32,'Indicadores PFGP'!A$2:$D$89,4,0) -> Percentual de cargos de liderança ocupados por servidores estatutários | C32: % de cargos de liderança ocupados por servidores estatutários | D32: Função | E32: FUNÇÃO | F32: Função | G32: DIGID | H32: DW-SIAPE
A33: 51 | B33: =VLOOKUP(A33,'Indicadores PFGP'!A$2:$D$89,4,0) -> Percentual de cargos de liderança ocupados por servidores estatutários | C33: % de cargos de liderança ocupados por servidores estatutários | D33: Nível da função | E33: NÍVEL FUNÇÃO | F33: Nível da função | G33: DIGID | H33: DW-SIAPE
A34: 51 | B34: =VLOOKUP(A34,'Indicadores PFGP'!A$2:$D$89,4,0) -> Percentual de cargos de liderança ocupados por servidores estatutários | C34: % de cargos de liderança ocupados por servidores estatutários | D34: Função | E34: SG_FUNCAO | F34: Função | G34: DIGID | H34: DataBricks | I34: Tabelão
A35: 51 | B35: =VLOOKUP(A35,'Indicadores PFGP'!A$2:$D$89,4,0) -> Percentual de cargos de liderança ocupados por servidores estatutários | C35: % de cargos de liderança ocupados por servidores estatutários | D35: Nível da função | E35: CO_NIVEL_FUNCAO | F35: Código do Nível da função | G35: DIGID | H35: DataBricks | I35: Tabelão
A36: 51 | B36: =VLOOKUP(A36,'Indicadores PFGP'!A$2:$D$89,4,0) -> Percentual de cargos de liderança ocupados por servidores estatutários | C36: % de cargos de liderança ocupados por servidores estatutários | D36: Nível da função | E36: SG_NIV_FUN | F36: Nível da função | G36: DIGID | H36: DataBricks | I36: Tabelão
A37: 51 | B37: =VLOOKUP(A37,'Indicadores PFGP'!A$2:$D$89,4,0) -> Percentual de cargos de liderança ocupados por servidores estatutários | C37: % de cargos de liderança ocupados por servidores estatutários | D37: Nome do Cargo | E37: NO_CARGO | F37: Nome do Cargo | G37: DIGID | H37: DataBricks | I37: Tabelão
A38: 51 | B38: =VLOOKUP(A38,'Indicadores PFGP'!A$2:$D$89,4,0) -> Percentual de cargos de liderança ocupados por servidores estatutários | C38: % de cargos de liderança ocupados por servidores estatutários | D38: Cargo de origem | E38: NO_CARGO_ORIGEM | F38: Nome do cargo de origem | G38: DIGID | H38: DataBricks | I38: Tabelão
A39: 52 | B39: equidade da distribuição dos cargos de liderança por origem territorial | C39: equidade da distribuição dos cargos de liderança por origem territorial | D39: Função | E39: FUNÇÃO | F39: Função | G39: DIGID | H39: DW-SIAPE
A40: 52 | B40: equidade da distribuição dos cargos de liderança por origem territorial | C40: equidade da distribuição dos cargos de liderança por origem territorial | D40: Nível da função | E40: NÍVEL FUNÇÃO | F40: Nível da função | G40: DIGID | H40: DW-SIAPE
...

Sheet Modelo Dados
A1: SG_ORGAO | B1: NO_ORGAO | C1: NO_NATUREZA_JURIDICA | D1: AGRUPAMENTO_NATJUR | E1: NO_COR_ORIGEM_ETNICA | F1: NO_SEXO | G1: NO_REGIAO_NATURALIDADE | H1: MES_REF | I1: ANO_REF | J1: ind_1 | K1: ind_2 | L1: ind_3 | M1: ind_4
A2: MAPA | B2: MINISTERIO DA AGRICULTURA E PECUARIA | C2: ADMINISTRACAO DIRETA FEDERAL | F2: NAO INFORMADO | G2: M | H2: NAO_SE_APLICA | I2: 2026
A3: C.EX | B3: COMANDO DO EXERCITO | C3: ADMINISTRACAO DIRETA FEDERAL | F3: PARDA | G3: F | H3: SUL | I3: 2026
A4: MAPA | B4: MINISTERIO DA AGRICULTURA E PECUARIA | C4: ADMINISTRACAO DIRETA FEDERAL | F4: NAO INFORMADO | G4: M | H4: CENTRO_OESTE | I4: 2026
A5: MEC | B5: MINISTERIO DA EDUCACAO | C5: ADMINISTRACAO DIRETA FEDERAL | F5: BRANCA | G5: M | H5: NORDESTE | I5: 2026
A6: MEC | B6: MINISTERIO DA EDUCACAO | C6: ADMINISTRACAO DIRETA FEDERAL | F6: PARDA | G6: M | H6: NORTE | I6: 2026

Sheet Marco Lógico Políticas
A1: Dimensão | B1: Item | C1: Ação | D1: Fase do Modelo Lógico | E1: Descrição do Indicador | F1: Status | G1: Finalidade do Monitoramento | H1: Difculdade de obtenção | I1: Linha de base | J1: Meta | K1: Frequência de Coleta | L1: Fonte
A2: 1. Planejamento da Força de Trabalho | B2: 1.2 Políticas de Diversidade e Inclusão | C2: Cotas para cargos comissão/função confiança (decreto 11.443/2023) | D2: Insumos | E2: Orçamento disponível para capacitação e sensibilização de gestores sobre o Decreto 11.443/23. | F2: Sugerido | G2: Verificar se os recursos financeiros e humanos são suficientes para a execução. | H2: Alta | K2: Semestral | L2: Órgão Setorial de Gestão de Pessoas / MIR / MGI
A3: 1. Planejamento da Força de Trabalho | B3: 1.2 Políticas de Diversidade e Inclusão | C3: Cotas para cargos comissão/função confiança (decreto 11.443/2023) | D3: Insumos | E3: Número de cargos de liderança disponíveis (ocupados/vagos) | F3: Obtido, não apresentado | G3: Monitorar viabilidade da implementação de cotas | H3: Moderada | K3: Mensal | L3: MGI / Sistema SIAPE
A4: 1. Planejamento da Força de Trabalho | B4: 1.2 Políticas de Diversidade e Inclusão | C4: Cotas para cargos comissão/função confiança (decreto 11.443/2023) | D4: Insumos | E4: Indicador 2: Índice de suficiência de vagas para cumprimento da meta racial | F4: Calculado | G4: Monitorar viabilidade da implementação de cotas | H4: Moderada
A5: 1. Planejamento da Força de Trabalho | B5: 1.2 Políticas de Diversidade e Inclusão | C5: Cotas para cargos comissão/função confiança (decreto 11.443/2023) | D5: Atividades | E5: Ações de capacitação e sensibilização de gestores sobre o Decreto 11.443/23. | F5: Sugerido | G5: Medir o esforço e as ações realizadas para transformar insumos em produtos. | H5: Alta | K5: Trimestral | L5: Unidades de Gestão de Pessoas dos Ministérios
A6: 1. Planejamento da Força de Trabalho | B6: 1.2 Políticas de Diversidade e Inclusão | C6: Cotas para cargos comissão/função confiança (decreto 11.443/2023) | D6: Produtos | E6: Quantidade de pessoas pretas e pardas nomeadas em cargos CCE e FCE de níveis 13 a 17 (liderança). | F6: Obtido, não apresentado | G6: Monitorar as entregas diretas e imediatas da política. | H6: Baixa | J6: 30% X Total de cargos | K6: Mensal | L6: MGI / Sistema SIAPE
A7: 1. Planejamento da Força de Trabalho | B7: 1.2 Políticas de Diversidade e Inclusão | C7: Cotas para cargos comissão/função confiança (decreto 11.443/2023) | D7: Resultados | E7: Indicador 1: Participação de pessoas negras em cargos CCE/FCE | F7: Calculado | G7: Avaliar mudanças de curto e médio prazo no comportamento das nomeações. | H7: Baixa
A8: 1. Planejamento da Força de Trabalho | B8: 1.2 Políticas de Diversidade e Inclusão | C8: Cotas para cargos comissão/função confiança (decreto 11.443/2023) | D8: Impactos | E8: Indicador 3: Índice de equidade de acesso a cargos FCE | F8: Calculado | G8: Verificar as mudanças de longo prazo na realidade do público-alvo. | H8: Baixa
A9: 1. Planejamento da Força de Trabalho | B9: 1.2 Políticas de Diversidade e Inclusão | C9: Cotas para cargos comissão/função confiança (decreto 11.443/2023) | D9: Impactos | E9: Indicador 4: Índice de equidade remuneratória por raça | F9: Em revisão | G9: Verificar as mudanças de longo prazo na realidade do público-alvo. | H9: Baixa | K9: Quadrienal (Ciclo do PPA) | L9: MGI / Sistema SIAPE
A10: 1. Planejamento da Força de Trabalho | B10: 1.1 DIMENSIONAMENTO DA FORÇA DE TRABALHO | C10: dimensionamento da força de trabalho (PORTARIA SEDGG/ME Nº 7.888, DE 1º DE SETEMBRO DE 2022)
A11: 1. Planejamento da Força de Trabalho | B11: 1.2 POLÍTICAS DE DIVERSIDADE E INCLUSÃO | C11: Cotas em concurso para negros, indígenas e quilombolas (Lei nº 15.142/25)
A12: 1. Planejamento da Força de Trabalho | B12: 1.2 POLÍTICAS DE DIVERSIDADE E INCLUSÃO | C12: Cota em concurso para PCD (Decreto 9.508/18)
A13: 1. Planejamento da Força de Trabalho | B13: 1.3 PROVISÃO DA FORÇA DE TRABALHO: CONCURSO PÚBLICO, CONTRATO TEMPORÁRIO, PROGRAMA DE ESTÁGIO E EMPREGO PÚBLICO | C13: Concursos Públicos - CPNU
A14: 1. Planejamento da Força de Trabalho | B14: 1.3 PROVISÃO DA FORÇA DE TRABALHO: CONCURSO PÚBLICO, CONTRATO TEMPORÁRIO, PROGRAMA DE ESTÁGIO E EMPREGO PÚBLICO | C14: Contratação Temporária
A15: 1. Planejamento da Força de Trabalho | B15: 1.3 PROVISÃO DA FORÇA DE TRABALHO: CONCURSO PÚBLICO, CONTRATO TEMPORÁRIO, PROGRAMA DE ESTÁGIO E EMPREGO PÚBLICO | C15: Estágio
A16: 1. Planejamento da Força de Trabalho | B16: 1.3 PROVISÃO DA FORÇA DE TRABALHO: CONCURSO PÚBLICO, CONTRATO TEMPORÁRIO, PROGRAMA DE ESTÁGIO E EMPREGO PÚBLICO | C16: Emprego Público
A17: 1. Planejamento da Força de Trabalho | B17: 1.4 MOVIMENTAÇÃO DE PESSOAL: CESSÃO, REQUISIÇÃO, COMPOSIÇÃO DA FORÇA DE TRABALHO E EXERCÍCIO DESCENTRALIZADO | C17: Cessão
A18: 1. Planejamento da Força de Trabalho | B18: 1.4 MOVIMENTAÇÃO DE PESSOAL: CESSÃO, REQUISIÇÃO, COMPOSIÇÃO DA FORÇA DE TRABALHO E EXERCÍCIO DESCENTRALIZADO | C18: Requisição
A19: 1. Planejamento da Força de Trabalho | B19: 1.4 MOVIMENTAÇÃO DE PESSOAL: CESSÃO, REQUISIÇÃO, COMPOSIÇÃO DA FORÇA DE TRABALHO E EXERCÍCIO DESCENTRALIZADO | C19: Composição Força Trabalho
A20: 1. Planejamento da Força de Trabalho | B20: 1.4 MOVIMENTAÇÃO DE PESSOAL: CESSÃO, REQUISIÇÃO, COMPOSIÇÃO DA FORÇA DE TRABALHO E EXERCÍCIO DESCENTRALIZADO | C20: Exercício Descentralizado
A21: 1. Planejamento da Força de Trabalho | B21: 1.4 MOVIMENTAÇÃO DE PESSOAL: CESSÃO, REQUISIÇÃO, COMPOSIÇÃO DA FORÇA DE TRABALHO E EXERCÍCIO DESCENTRALIZADO | C21: Aproveitamento quadro em extinção (Lei 13681/18)
... A60: 6. APOSENTAÇÃO, PENSÕES E DESLIGAMENTOS | B60: 6.3 GESTÃO DA PREVIDÊNCIA E CONFORMIDADE PREVIDENCIÁRIA | C60: Centralização da gestão

Sheet Planilha1
A1: Dimensão 1: Planejamento, Diagnóstico da Força de Trabalho e Processo Seletivo​ | B1: (Tudo)
A2: Dimensão 2: Carreiras, Cargos, Progressão e Promoção​ | B2: (Tudo)
A3: Dimensão 3: Alocação, Ambientação, Estágio Probatório e Bem-Estar​ | B3: (Tudo)
A4: Dimensão 4: Desenvolvimento e Desempenho de Pessoas e Formação de Lideranças Públicas​ | B4: (Tudo)
A5: Dimensão 5: Remuneração, Benefícios, Reconhecimento e Recompensas Não Pecuniárias​ | B5: (Tudo)
A6: Dimensão 6: Aposentação, Pensões e Desligamentos | B6: (Tudo)
A8: Projeto Estruturante | B8: Indicador | C8: Contagem de id_indicador
A9: ALOCAÇÃO ESTRATÉGICA: PERFIL PROFISSIOGRÁFICO E CURRÍCULO & OPORTUNIDADES | C9: 2
A10: AMBIENTAÇÃO E GESTÃO DO ESTÁGIO PROBATÓRIO | C10: 2
A11: DESENVOLVIMENTO PROFISSIONAL (PNDP) | C11: 2
A12: DIAGNÓSTICO/DIMENSIONAMENTO DA FORÇA DE TRABALHO (DDFT) | C12: 1
A13: ENFRENTAMENTO DO ASSÉDIO E DA DISCRIMINAÇÃO (PFPEAD) | C13: 1
A14: GESTÃO E DESEMPENHO (PGD) | C14: 3
A15: MODERNIZAÇÃO, DIGITALIZAÇÃO, GESTÃO E CONFORMIDADE DO RPPS | C15: 2
A16: MOVIMENTAÇÃO DE PESSOAL: CESSÃO, REQUISIÇÃO, COMPOSIÇÃO DA FORÇA DE TRABALHO E EXERCÍCIO DESCENTRALIZADO | C16: 1
A17: POLÍTICA FEDERAL DE APOSENTAÇÃO: PREPARAÇÃO E TRANSIÇÃO PARA A APOSENTADORIA, VALORIZAÇÃO DO LEGADO E PENSÕES | C17: 1
A18: POLÍTICA FEDERAL DE REMUNERAÇÕES: FOLHA DE PAGAMENTOS E CONSIGNAÇÕES | C18: 4
A19: PROGRESSÃO E PROMOÇÃO FUNCIONAL: VALORIZAÇÃO PROFISSIONAL NAS CARREIRAS | C19: 1
A20: PROVISÃO DA FORÇA DE TRABALHO: CONCURSO PÚBLICO, CONTRATO TEMPORÁRIO, PROGRAMA DE ESTÁGIO E EMPREGO PÚBLICO | C20: 2
... A22: SUBSISTEMA INTEGRADO DE ATENÇÃO À SAÚDE DO SERVIDOR PÚBLICO FEDERAL (SIASS) | C22: 1
A23: (vazio) | B23: % de servidores submetidos à avaliação de competências de liderança | C23: 1
B24: % de servidores submetidos à avaliação de desempenho 360º (?) | C24: 1
B25: Distribuição observada por forma de provimento (estatutário, temporário, emprego público, comissionado) | C25: 1
B26: Distribuição planejada por forma de provimento (estatutário, temporário, emprego público, comissionado) | C26: 1
B27: equidade de distribuição dos servidores públicos, vis a vis distribuição demográfica na população, por: 1) gênero; 2) raça; 3) origem territorial; 4) faixa etária | C27: 1
B28: histograma da distribuição dos servidores de carreiras transversais / não transversais por número de áreas temáticas e órgãos em que atuaram | C28: 1
B29: indicador de racionalidade de carreiras (?) | C29: 1
B30: indicador de racionalidade de estruturas remuneratórias (?) | C30: 1
B31: indicador de valorização e reconhecimento não pecuniário (?) | C31: 1
B32: Indicadores de clima e percepção de respeito no ambiente de trabalho | C32: 1
B33: indicadores de turnover de lideranças | C33: 1
B34: indicadores de turnover; | C34: 1
B35: Intenção de saída / permanência | C35: 1
... B77: Tempo médio de permanência dos servidores por lotação (transversais / não transversais, em áreas temáticas, em órgãos, em secretarias) | C77: 1
A78: (vazio) Total | C78: 55
A79: Total Geral | C79: 81
